<?xml version="1.0"?>
<!-- Revolute-Revolute Manipulator -->
<robot name="snake_robot" xmlns:xacro="http://www.ros.org/wiki/xacro">

  <material name="grey">
    <color rgba="0.2 0.2 0.2 1.0"/>
  </material>


  <link name="world">
  </link>

  <joint name="world_fixed" type="fixed">
    <origin xyz="0 0 0" rpy="0 0 0"/>
    <parent link="world"/>
    <child link="base"/>
  </joint>

  <link name="base">
  </link>

  <joint name="base_fixed" type="fixed">
    <origin xyz="0 0 0.0" rpy="0 0 0"/>
    <parent link="base"/>
    <child link="dxl_rx_28_set"/>
  </joint>

  <link name="dxl_rx_28_set">
    <visual>
      <origin xyz="0 0 0" rpy="0 0 0"/>
      <geometry>
        <mesh filename="package://snake_robot_description/meshes/dxl_rx_28_set.stl" scale="0.001 0.001 0.001"/>
      </geometry>
      <material name="grey"/>
    </visual>
  </link>

  <joint name="lidar_joint" type="revolute">
    <parent link="dxl_rx_28_set"/>
    <child link="lidar_set"/>
    <origin xyz="0 0 0.02075" rpy="0 0 0"/>
    <axis xyz="0 0 1"/>
    <limit velocity="6.5" effort="1000" lower="${-pi*0.6}" upper="${pi*0.6}" />
    <dynamics damping="0.1" friction="0.0" />
  </joint> -->

  <link name="lidar_set">
    <visual>
      <origin xyz="0 0 0.03065" rpy="0 0 0"/>
      <geometry>
        <mesh filename="package://snake_robot_description/meshes/lidar_set.stl" scale="0.001 0.001 0.001"/>
      </geometry>
      <material name="grey"/>
    </visual>
  </link>

  <!-- lidar joint -->
  <joint name="lidar_fixed" type="fixed">
    <origin xyz="0.0 0.0 0.03065" rpy="1.5707963268 0 0"/>
    <parent link="lidar_set"/>
    <child link="lidar_link"/>
  </joint> 

  <!-- lidar link -->
  <link name="lidar_link">
  </link>

</robot>
